1899164#: Could not create directory '/.ssh'.
1899164#: Failed to add the host to the list of known hosts (/.ssh/known_hosts).
1899164#: Environment:
1899164#:   USER=slot4
1899164#:   LOGNAME=slot4
1899164#:   HOME=/var/lib/condor/execute/slot4
1899164#:   PATH=/usr/local/bin:/bin:/usr/bin
1899164#:   MAIL=/var/mail/slot4
1899164#:   SHELL=/bin/bash
1899164#:   SSH_CLIENT=2607:f720:1700:31d::61 39153 5001
1899164#:   SSH_CONNECTION=2607:f720:1700:31d::61 39153 2607:f388:107c:502::c 5001
1899164#: Could not chdir to home directory /var/lib/condor/execute/slot4: No such file or directory
Traceback (most recent call last):
  File "/var/opt/condor/execute/dir_1898489/condor_exec.exe", line 173, in <module>
    main(sys.argv[1:])
  File "/var/opt/condor/execute/dir_1898489/condor_exec.exe", line 169, in main
    performPlacement(inputfile,outputfile)
  File "/var/opt/condor/execute/dir_1898489/condor_exec.exe", line 88, in performPlacement
    pMover.client(host,port)
  File "/var/opt/condor/execute/dir_1898489/UDTMover.py", line 43, in client
    self.run()
  File "/var/opt/condor/execute/dir_1898489/DataMover.py", line 143, in run
    errhandler=self.stderrHandler)
  File "/var/opt/condor/execute/dir_1898489/TimedExec.py", line 100, in runTimedCmd
    stderr=errtype, stdout=outtype)
  File "/usr/lib64/python2.6/subprocess.py", line 642, in __init__
    errread, errwrite)
  File "/usr/lib64/python2.6/subprocess.py", line 1238, in _execute_child
    raise child_exception
OSError: [Errno 2] No such file or directory
